2023-05-03 20:41:29,914 INFO: Microblog startup [in D:\实验作业\2023-25 Web应用开发\project\code\11\app\__init__.py:45]
2023-05-03 20:41:44,207 ERROR: Exception on /edit_profile [POST] [in D:\005Anaconda\lib\site-packages\flask\app.py:1744]
Traceback (most recent call last):
  File "D:\005Anaconda\lib\site-packages\flask\app.py", line 2528, in wsgi_app
    response = self.full_dispatch_request()
  File "D:\005Anaconda\lib\site-packages\flask\app.py", line 1825, in full_dispatch_request
    rv = self.handle_user_exception(e)
  File "D:\005Anaconda\lib\site-packages\flask\app.py", line 1823, in full_dispatch_request
    rv = self.dispatch_request()
  File "D:\005Anaconda\lib\site-packages\flask\app.py", line 1799, in dispatch_request
    return self.ensure_sync(self.view_functions[rule.endpoint])(**view_args)
  File "D:\005Anaconda\lib\site-packages\flask_login\utils.py", line 290, in decorated_view
    return current_app.ensure_sync(func)(*args, **kwargs)
  File "D:\实验作业\2023-25 Web应用开发\project\code\11\app\routes.py", line 90, in edit_profile
    if form.validate_on_submit():
  File "D:\005Anaconda\lib\site-packages\flask_wtf\form.py", line 86, in validate_on_submit
    return self.is_submitted() and self.validate(extra_validators=extra_validators)
TypeError: validate() got an unexpected keyword argument 'extra_validators'
2023-05-03 20:49:17,777 INFO: Microblog startup [in D:\实验作业\2023-25 Web应用开发\project\code\11\app\__init__.py:45]
2023-05-03 20:49:27,004 ERROR: Exception on /edit_profile [POST] [in D:\005Anaconda\lib\site-packages\flask\app.py:1744]
Traceback (most recent call last):
  File "D:\005Anaconda\lib\site-packages\flask\app.py", line 2528, in wsgi_app
    response = self.full_dispatch_request()
  File "D:\005Anaconda\lib\site-packages\flask\app.py", line 1825, in full_dispatch_request
    rv = self.handle_user_exception(e)
  File "D:\005Anaconda\lib\site-packages\flask\app.py", line 1823, in full_dispatch_request
    rv = self.dispatch_request()
  File "D:\005Anaconda\lib\site-packages\flask\app.py", line 1799, in dispatch_request
    return self.ensure_sync(self.view_functions[rule.endpoint])(**view_args)
  File "D:\005Anaconda\lib\site-packages\flask_login\utils.py", line 290, in decorated_view
    return current_app.ensure_sync(func)(*args, **kwargs)
  File "D:\实验作业\2023-25 Web应用开发\project\code\11\app\routes.py", line 90, in edit_profile
    if form.validate_on_submit():
  File "D:\005Anaconda\lib\site-packages\flask_wtf\form.py", line 86, in validate_on_submit
    return self.is_submitted() and self.validate(extra_validators=extra_validators)
TypeError: validate() got an unexpected keyword argument 'extra_validators'
2023-05-03 21:00:36,855 INFO: Microblog startup [in D:\实验作业\2023-25 Web应用开发\project\code\11\app\__init__.py:45]
2023-05-03 21:00:53,374 ERROR: Exception on /edit_profile [POST] [in D:\005Anaconda\lib\site-packages\flask\app.py:1744]
Traceback (most recent call last):
  File "D:\005Anaconda\lib\site-packages\flask\app.py", line 2528, in wsgi_app
    response = self.full_dispatch_request()
  File "D:\005Anaconda\lib\site-packages\flask\app.py", line 1825, in full_dispatch_request
    rv = self.handle_user_exception(e)
  File "D:\005Anaconda\lib\site-packages\flask\app.py", line 1823, in full_dispatch_request
    rv = self.dispatch_request()
  File "D:\005Anaconda\lib\site-packages\flask\app.py", line 1799, in dispatch_request
    return self.ensure_sync(self.view_functions[rule.endpoint])(**view_args)
  File "D:\005Anaconda\lib\site-packages\flask_login\utils.py", line 290, in decorated_view
    return current_app.ensure_sync(func)(*args, **kwargs)
  File "D:\实验作业\2023-25 Web应用开发\project\code\11\app\routes.py", line 90, in edit_profile
    if form.validate_on_submit():
  File "D:\005Anaconda\lib\site-packages\flask_wtf\form.py", line 86, in validate_on_submit
    return self.is_submitted() and self.validate(extra_validators=extra_validators)
TypeError: validate() got an unexpected keyword argument 'extra_validators'
2023-05-03 21:01:08,968 ERROR: Exception on /edit_profile [POST] [in D:\005Anaconda\lib\site-packages\flask\app.py:1744]
Traceback (most recent call last):
  File "D:\005Anaconda\lib\site-packages\flask\app.py", line 2528, in wsgi_app
    response = self.full_dispatch_request()
  File "D:\005Anaconda\lib\site-packages\flask\app.py", line 1825, in full_dispatch_request
    rv = self.handle_user_exception(e)
  File "D:\005Anaconda\lib\site-packages\flask\app.py", line 1823, in full_dispatch_request
    rv = self.dispatch_request()
  File "D:\005Anaconda\lib\site-packages\flask\app.py", line 1799, in dispatch_request
    return self.ensure_sync(self.view_functions[rule.endpoint])(**view_args)
  File "D:\005Anaconda\lib\site-packages\flask_login\utils.py", line 290, in decorated_view
    return current_app.ensure_sync(func)(*args, **kwargs)
  File "D:\实验作业\2023-25 Web应用开发\project\code\11\app\routes.py", line 90, in edit_profile
    if form.validate_on_submit():
  File "D:\005Anaconda\lib\site-packages\flask_wtf\form.py", line 86, in validate_on_submit
    return self.is_submitted() and self.validate(extra_validators=extra_validators)
TypeError: validate() got an unexpected keyword argument 'extra_validators'
2023-05-03 21:01:15,331 ERROR: Exception on /edit_profile [POST] [in D:\005Anaconda\lib\site-packages\flask\app.py:1744]
Traceback (most recent call last):
  File "D:\005Anaconda\lib\site-packages\flask\app.py", line 2528, in wsgi_app
    response = self.full_dispatch_request()
  File "D:\005Anaconda\lib\site-packages\flask\app.py", line 1825, in full_dispatch_request
    rv = self.handle_user_exception(e)
  File "D:\005Anaconda\lib\site-packages\flask\app.py", line 1823, in full_dispatch_request
    rv = self.dispatch_request()
  File "D:\005Anaconda\lib\site-packages\flask\app.py", line 1799, in dispatch_request
    return self.ensure_sync(self.view_functions[rule.endpoint])(**view_args)
  File "D:\005Anaconda\lib\site-packages\flask_login\utils.py", line 290, in decorated_view
    return current_app.ensure_sync(func)(*args, **kwargs)
  File "D:\实验作业\2023-25 Web应用开发\project\code\11\app\routes.py", line 90, in edit_profile
    if form.validate_on_submit():
  File "D:\005Anaconda\lib\site-packages\flask_wtf\form.py", line 86, in validate_on_submit
    return self.is_submitted() and self.validate(extra_validators=extra_validators)
TypeError: validate() got an unexpected keyword argument 'extra_validators'
2023-05-04 14:54:30,775 INFO: Microblog startup [in D:\实验作业\2023-25 Web应用开发\project\code\11\app\__init__.py:60]
2023-05-04 14:54:43,246 ERROR: Exception on /edit_profile [POST] [in D:\005Anaconda\lib\site-packages\flask\app.py:1744]
Traceback (most recent call last):
  File "D:\005Anaconda\lib\site-packages\flask\app.py", line 2528, in wsgi_app
    response = self.full_dispatch_request()
  File "D:\005Anaconda\lib\site-packages\flask\app.py", line 1825, in full_dispatch_request
    rv = self.handle_user_exception(e)
  File "D:\005Anaconda\lib\site-packages\flask\app.py", line 1823, in full_dispatch_request
    rv = self.dispatch_request()
  File "D:\005Anaconda\lib\site-packages\flask\app.py", line 1799, in dispatch_request
    return self.ensure_sync(self.view_functions[rule.endpoint])(**view_args)
  File "D:\005Anaconda\lib\site-packages\flask_login\utils.py", line 290, in decorated_view
    return current_app.ensure_sync(func)(*args, **kwargs)
  File "D:\实验作业\2023-25 Web应用开发\project\code\11\app\routes.py", line 90, in edit_profile
    if form.validate_on_submit():
  File "D:\005Anaconda\lib\site-packages\flask_wtf\form.py", line 86, in validate_on_submit
    return self.is_submitted() and self.validate(extra_validators=extra_validators)
TypeError: validate() got an unexpected keyword argument 'extra_validators'
2023-05-04 15:15:14,347 INFO: Microblog startup [in D:\实验作业\2023-25 Web应用开发\project\code\11\app\__init__.py:49]
2023-05-04 15:15:21,844 ERROR: Exception on /edit_profile [POST] [in D:\005Anaconda\lib\site-packages\flask\app.py:1744]
Traceback (most recent call last):
  File "D:\005Anaconda\lib\site-packages\flask\app.py", line 2528, in wsgi_app
    response = self.full_dispatch_request()
  File "D:\005Anaconda\lib\site-packages\flask\app.py", line 1825, in full_dispatch_request
    rv = self.handle_user_exception(e)
  File "D:\005Anaconda\lib\site-packages\flask\app.py", line 1823, in full_dispatch_request
    rv = self.dispatch_request()
  File "D:\005Anaconda\lib\site-packages\flask\app.py", line 1799, in dispatch_request
    return self.ensure_sync(self.view_functions[rule.endpoint])(**view_args)
  File "D:\005Anaconda\lib\site-packages\flask_login\utils.py", line 290, in decorated_view
    return current_app.ensure_sync(func)(*args, **kwargs)
  File "D:\实验作业\2023-25 Web应用开发\project\code\11\app\routes.py", line 90, in edit_profile
    if form.validate_on_submit():
  File "D:\005Anaconda\lib\site-packages\flask_wtf\form.py", line 86, in validate_on_submit
    return self.is_submitted() and self.validate(extra_validators=extra_validators)
TypeError: validate() got an unexpected keyword argument 'extra_validators'
2023-05-04 15:58:36,930 INFO: Microblog startup [in D:\实验作业\2023-25 Web应用开发\project\code\11\app\__init__.py:49]
